<?xml version="1.0" encoding="utf-8"?><messages><msg code="0" type="2">Start Time: Friday, February 14, 2025 1:43:29 PM</msg><msg code="0" type="0">!!- starting preparing data!!!.</msg><msg code="1" type="100">﻿Traceback (most recent call last):
﻿  File "D:\github_projects\geodata-pre-ingest\processing_tools.pyt", line 89, in execute
﻿    arcpy.AddMessage(projected_batch_directory_path)
﻿  File "C:\Program Files\ArcGIS\Pro\Resources\ArcPy\arcpy\__init__.py", line 335, in AddMessage
﻿    return gp.addMessage(message)
﻿           ^^^^^^^^^^^^^^^^^^^^^^
﻿  File "C:\Program Files\ArcGIS\Pro\Resources\ArcPy\arcpy\geoprocessing\_base.py", line 190, in addMessage
﻿    self._gp.AddMessage(*gp_fixargs(args, True)))
﻿    ^^^^^^^^^^^^^^^^^^^^^^^^^^^^^^^^^^^^^^^^^^^^
﻿AttributeError: Object: Error in parsing arguments for AddMessage
</msg><msg code="-2147467259" type="100">Failed to execute (PrepareBatchTool).</msg><msg code="0" type="3">Failed at Friday, February 14, 2025 1:43:29 PM (Elapsed Time: 0.05 seconds)</msg></messages>